2023-09-04 17:22:03 | Exception occurred: Email already exists
Traceback (most recent call last):
  File "main.py", line 12, in __init__
    self.validate()
  File "main.py", line 57, in validate
    raise exceptions.EmailAlreadyExistsException("Email already exists")
exceptions.EmailAlreadyExistsException: Email already exists

